<?xml version="1.0"?>
<!-- New QCar Description -->
<robot name="QCar" xmlns:xacro="http://www.ros.org/wiki/xacro">
	<xacro:macro name="QCar_" params="parent prefix *origin">
		<!-- ******************** QCar Constants ******************** -->
		<xacro:include filename="$(find qcar_gazebo)/urdf/qcar.gazebo.xacro" />
		<xacro:include filename="$(find qcar_gazebo)/urdf/qcar.materials.xacro" />

		<!-- Degree-to-radian conversions -->
		<xacro:property name="degrees_30" value="0.523599"/>
		<xacro:property name="degrees_45" value="0.785398163"/>
		<xacro:property name="degrees_90" value="1.57079633"/>

		<!-- chassis_length is measured along the x axis, chassis_width along the y axis, and chassis_height along the z axis. -->
		<xacro:property name="chassis_length" value="0.425"/>
		<xacro:property name="chassis_width" value="0.192"/>
		<xacro:property name="chassis_height" value="0.182"/>
		<xacro:property name="chassis_mass" value="2.552"/>

		<xacro:property name="hub_dia" value="0.015"/>
		<xacro:property name="tire_dia" value="0.053"/>
		<xacro:property name="tire_width" value="0.025"/>
		<xacro:property name="hex_hub_depth" value="0.018"/>
		<xacro:property name="wheel_mass" value="0.035"/>

		<xacro:property name="wheelbase" value="0.265"/>
		<xacro:property name="hex_hub_dist" value="0.285"/>
		<xacro:property name="axle_length" value="0.025"/>
		<xacro:property name="axle_eff_limit" value="5.12766"/>
		<xacro:property name="axle_vel_limit" value="244.8696"/>

		<xacro:property name="servo_stall_torque" value="0.5649"/>
		<xacro:property name="servo_no_load_speed" value="4.553"/>

		<xacro:property name="ctrl_period" value="0.01"/>

		<!-- ******************** Macros ******************** -->

		<!-- Null inertial element. This is needed to make the model work with
		Gazebo. -->
		<xacro:macro name="null_inertial">
			<inertial>
				<origin rpy="0 0 0" xyz="0 0 0"/>
				<mass value="0.001"/>
				<inertia ixx="0.001" ixy="0" ixz="0" iyy="0.001" iyz="0" izz="0.001"/>
			</inertial>
		</xacro:macro>

		<!-- Inertia of a solid cuboid. Width is measured along the x axis, depth along the y axis, and height along the z axis. -->
		<xacro:macro name="solid_cuboid_inertial" params="width depth height mass *origin">
			<inertial>
				<xacro:insert_block name="origin"/>
				<mass value="${mass}"/>
				<inertia ixx="${mass * (depth * depth + height * height) / 12}"
						ixy="0" ixz="0"
						iyy="${mass * (width * width + height * height) / 12}"
						iyz="0"
						izz="${mass * (width * width + depth * depth) / 12}"/>
			</inertial>
		</xacro:macro>

		<!-- Inertia of a thick-walled cylindrical tube with open ends. Height is
		measured along the z axis, which is the tube's axis. inner_rad and
		outer_rad are the tube's inner and outer radii, respectively. -->
		<xacro:macro name="thick_walled_tube_inertial" params="inner_rad outer_rad height mass">
			<inertial>
				<mass value="${mass}"/>
				<inertia ixx="${(1 / 12) * mass * (3 * (inner_rad * inner_rad + outer_rad * outer_rad) + height * height)}"
						ixy="0" ixz="0"
						iyy="${(1 / 12) * mass * (3 * (inner_rad * inner_rad + outer_rad * outer_rad) + height * height)}"
						iyz="0"
						izz="${mass * (inner_rad * inner_rad + outer_rad * outer_rad) / 2}"/>
			</inertial>
		</xacro:macro>

		<!-- ******************** QCar Footprint ******************** -->
		<joint name="base_joint" type="fixed">
			<parent link="${parent}"/>
			<child link="${prefix}base_link" />
			<xacro:insert_block name="origin" />
		</joint>

		<!-- ******************** QCar Base ******************** -->
		<link name="base_link">
			<visual>
				<origin xyz="0 0 0"/>
				<geometry>
					<mesh filename="file:///$(find qcar_gazebo)/meshes/QCarBody.stl" scale="0.001 0.001 0.001"/>
				</geometry>
				<material name="RED">
					<color rgba="${255/255} ${0/255} ${0/255} 1.0" />
				</material>
			</visual>

			<collision>
				<origin xyz="0 0 0"/> 
				<geometry>
					<!--<box size="${chassis_length} ${chassis_width} ${chassis_height}"/> -->
					<mesh filename="file:///$(find qcar_gazebo)/meshes/QCarBody.stl" scale="0.001 0.001 0.001"/>
				</geometry>
			</collision>

			<xacro:solid_cuboid_inertial width="${chassis_length}" depth="${chassis_width}" height="${chassis_height}" mass="${chassis_mass}">
				<origin xyz="0 0 0"/>
			</xacro:solid_cuboid_inertial>
		</link>

		<gazebo reference="base_link">
			<material>Gazebo/Red</material>
		</gazebo>

		<!-- ******************** QCar Sensors & Chassis ******************** -->
		<link name="lidar">
			<visual>
				<origin rpy="0 0 0" xyz="0 0 0"/>
				<geometry>
					<mesh filename="file:///$(find qcar_gazebo)/meshes/QCarLidar.stl" scale="0.001 0.001 0.001"/>
				</geometry>
			<material name="blue"/>
			</visual>

			<collision>
				<origin rpy="0 0 0" xyz="0 0 0"/>
				<geometry>
					<mesh filename="file:///$(find qcar_gazebo)/meshes/QCarLidar.stl" scale="0.001 0.001 0.001"/>
				</geometry>
			</collision>

			<inertial>
				<origin rpy="0 0 0" xyz="0 0 0"/>
				<mass value="0.1"/>
				<inertia ixx="0.001" ixy="0" ixz="0" iyy="0.001" iyz="0" izz="0.001"/>
			</inertial>
		</link>

		<joint name="body_lidar_joint" type="fixed">
			<parent link="base_link"/>
			<child link="lidar"/>
			<origin rpy="0 0 0" xyz="-0.01227 -0.00045 0.16152"/>
		</joint>

		<!-- TODO Add CSI Camera Joints -->

		<gazebo reference="lidar">
			<material>Gazebo/Blue</material>
		</gazebo>

		<!-- ******************** QCar Steering and Axles ******************** -->
		<link name="left_steering_link">
			<visual>
				<origin rpy="0 0 0" xyz=" 0 0 0"/>
				<geometry>
					<mesh filename="file:///$(find qcar_gazebo)/meshes/QCarSteeringHubL.stl" scale="0.001 0.001 0.001"/>
				</geometry>
				<material name="orange"/>
			</visual>

			<collision>
				<origin rpy="0 0 0" xyz="0 0 0"/>
				<geometry>
					<mesh filename="file:///$(find qcar_gazebo)/meshes/QCarSteeringHubL.stl" scale="0.001 0.001 0.001"/>
				</geometry>
			</collision>

			<xacro:null_inertial/>
		</link>

		<joint name="left_front_position_joint" type="fixed">
			<parent link="base_link"/>
			<child link="left_steering_link"/>
			<origin rpy="0 0 0" xyz="0.12960 0.05590 0.03338"/>
		</joint>

		<link name="left_front_axle_carrier">
			<xacro:null_inertial/>
		</link>

		<joint name="left_steering_joint" type="revolute">
			<parent link="left_steering_link"/>
			<child link="left_front_axle_carrier"/>
			<origin xyz="0 0 0" rpy="0 0 0" />
			<axis xyz = "0 0 1"/> <!--0 0 1 -->
			<limit lower="-0.523599" upper="0.523599" effort="0.5649" velocity="4.553"/>
		</joint>

		<link name="right_steering_link">
			<visual>
				<origin rpy="0 0 3.14" xyz=" 0 0 0"/>
				<geometry>
					<mesh filename="file:///$(find qcar_gazebo)/meshes/QCarSteeringHubL.stl" scale="0.001 0.001 0.001"/>
				</geometry>
			</visual>

			<collision>
				<origin rpy="0 0 0" xyz="0 0 0"/>
				<geometry>
					<mesh filename="file:///$(find qcar_gazebo)/meshes/QCarSteeringHubL.stl" scale="0.001 0.001 0.001"/>
				</geometry>
			</collision>

			<xacro:null_inertial/>
		</link>

		<joint name="right_front_position_joint" type="fixed">
			<parent link="base_link"/>
			<child link="right_steering_link"/>
			<origin rpy="0 0 0" xyz="0.12960 -0.05590 0.03338"/>
		</joint>

		<link name="right_front_axle_carrier">
			<xacro:null_inertial/>
		</link>

		<joint name="right_steering_joint" type="revolute">
			<parent link="right_steering_link"/>
			<child link="right_front_axle_carrier"/>
			<origin xyz="0 0 0" rpy="0 0 0" />
			<axis xyz = "0 0 1"/> <!--0 0 1 -->
			<limit lower="-0.523599" upper="0.523599" effort="0.5649" velocity="4.553"/>
		</joint>

		<link name="left_rear_axle_carrier">
			<xacro:null_inertial/>
		</link>

		<joint name="left_rear_position_joint" type="fixed">
			<parent link="base_link"/>
			<child link="left_rear_axle_carrier"/>
			<origin rpy="0 0 0" xyz="-0.12765 0.05610 0.03338"/>
		</joint>

		<link name="right_rear_axle_carrier">
			<xacro:null_inertial/>
		</link>

		<joint name="right_rear_position_joint" type="fixed">
			<parent link="base_link"/>
			<child link="right_rear_axle_carrier"/>
			<origin rpy="0 0 0" xyz="-0.12765 -0.05610 0.03338"/>
		</joint>

		<!-- ******************** QCar Wheels ******************** -->
		<link name="left_front_wheel">
			<visual>
				<origin rpy="0 0 0" xyz="0 0 0"/>
				<geometry>
					<mesh filename="file:///$(find qcar_gazebo)/meshes/QCarWheel.stl" scale="0.001 0.001 0.001"/>
				</geometry>
				<material name="RED">
					<color rgba="${255/255} ${0/255} ${0/255} 1.0" />
				</material>
			</visual>

			<collision>
				<origin rpy="0 0 0" xyz="0 0 0"/>
				<geometry>
					<mesh filename="file:///$(find qcar_gazebo)/meshes/QCarWheel.stl" scale="0.001 0.001 0.001"/>
				</geometry>
			</collision>

			<xacro:thick_walled_tube_inertial inner_rad="${hub_dia / 2}" outer_rad="${tire_dia / 2}" height="${tire_width}" mass="${wheel_mass}"/>
		</link>

		<joint name="left_front_axle" type="revolute">
			<parent link="left_front_axle_carrier"/>
			<child link="left_front_wheel"/>
			<axis xyz="0 -1 0"/> <!-- 0 0 -1-->
			<origin rpy="0 0 3.14159"/>
			<limit upper="3.1415" lower="-3.1415" effort="5.12766" velocity="244.8696"/>
			<dynamics damping="0.1" friction="0.1"/>
		</joint>

		<link name="right_front_wheel">
			<visual>
				<origin rpy="0 0 0" xyz="0 0 0"/>
				<geometry>
					<mesh filename="file:///$(find qcar_gazebo)/meshes/QCarWheel.stl" scale="0.001 0.001 0.001"/>
				</geometry>
				<material name="RED">
					<color rgba="${255/255} ${0/255} ${0/255} 1.0" />
				</material>
			</visual>

			<collision>
				<origin rpy="0 0 0" xyz="0 0 0"/>
				<geometry>
					<mesh filename="file:///$(find qcar_gazebo)/meshes/QCarWheel.stl" scale="0.001 0.001 0.001"/>
				</geometry>
			</collision>

			<xacro:thick_walled_tube_inertial inner_rad="${hub_dia / 2}" outer_rad="${tire_dia / 2}" height="${tire_width}" mass="${wheel_mass}"/>
		</link>

		<joint name="right_front_axle" type="revolute">
			<parent link="right_front_axle_carrier"/>
			<child link="right_front_wheel"/>
			<origin rpy="0 0 0"/>
			<axis xyz="0 1 0"/> <!-- 0 0 1-->
			<limit upper="3.1415" lower="-3.1415" effort="5.12766" velocity="244.8696"/>
			<dynamics damping="0.1" friction="0.1"/>
		</joint>

		<link name="left_rear_wheel">
			<visual>
				<origin rpy="0 0 0" xyz="0 0 0"/>
				<geometry>
					<mesh filename="file:///$(find qcar_gazebo)/meshes/QCarWheel.stl" scale="0.001 0.001 0.001"/>
				</geometry>
				<material name="RED">
					<color rgba="${255/255} ${0/255} ${0/255} 1.0" />
				</material>
			</visual>

			<collision>
				<origin rpy="0 0 0" xyz="0 0 0"/>
				<geometry>
					<mesh filename="file:///$(find qcar_gazebo)/meshes/QCarWheel.stl" scale="0.001 0.001 0.001"/>
				</geometry>
			</collision>

			<xacro:thick_walled_tube_inertial inner_rad="${hub_dia / 2}" outer_rad="${tire_dia / 2}" height="${tire_width}" mass="${wheel_mass}"/>
		</link>

		<joint name="left_rear_axle" type="revolute">
			<parent link="left_rear_axle_carrier"/>
			<child link="left_rear_wheel"/>
			<axis xyz="0 -1 0"/> <!-- 0 0 -1 -->
			<origin rpy="0 0 3.14159"/>
			<limit upper="3.1415" lower="-3.1415" effort="5.12766" velocity="244.8696"/>
			<dynamics damping="0.1" friction="0.1"/>
		</joint>

		<link name="right_rear_wheel">
			<visual>
				<origin rpy="0 0 0" xyz="0 0 0"/>
				<geometry>
					<mesh filename="file:///$(find qcar_gazebo)/meshes/QCarWheel.stl" scale="0.001 0.001 0.001"/>
				</geometry>
				<material name="RED">
					<color rgba="${255/255} ${0/255} ${0/255} 1.0" />
				</material>
			</visual>

			<collision>
				<origin rpy="0 0 0" xyz="0 0 0"/>
				<geometry>
					<mesh filename="file:///$(find qcar_gazebo)/meshes/QCarWheel.stl" scale="0.001 0.001 0.001"/>
				</geometry>
			</collision>

			<xacro:thick_walled_tube_inertial inner_rad="${hub_dia / 2}" outer_rad="${tire_dia / 2}" height="${tire_width}" mass="${wheel_mass}"/>
		</link>

		<joint name="right_rear_axle" type="revolute">
			<parent link="right_rear_axle_carrier"/>
			<child link="right_rear_wheel"/>
			<axis xyz="0 1 0"/>
			<origin rpy="0 0 0"/>
			<limit upper="3.1415" lower="-3.1415" effort="5.12766" velocity="244.8696"/>
			<dynamics damping="0.1" friction="0.1"/>
		</joint>

	</xacro:macro>
</robot>

